2020-05-15 15:25:55,563 ERROR: Exception on /view_answered [GET] [in /Users/cham/Desktop/webproj2/faze/lib/python3.8/site-packages/flask/app.py:1891]
Traceback (most recent call last):
  File "/Users/cham/Desktop/webproj2/faze/lib/python3.8/site-packages/flask/app.py", line 2447, in wsgi_app
    response = self.full_dispatch_request()
  File "/Users/cham/Desktop/webproj2/faze/lib/python3.8/site-packages/flask/app.py", line 1952, in full_dispatch_request
    rv = self.handle_user_exception(e)
  File "/Users/cham/Desktop/webproj2/faze/lib/python3.8/site-packages/flask/app.py", line 1821, in handle_user_exception
    reraise(exc_type, exc_value, tb)
  File "/Users/cham/Desktop/webproj2/faze/lib/python3.8/site-packages/flask/_compat.py", line 39, in reraise
    raise value
  File "/Users/cham/Desktop/webproj2/faze/lib/python3.8/site-packages/flask/app.py", line 1950, in full_dispatch_request
    rv = self.dispatch_request()
  File "/Users/cham/Desktop/webproj2/faze/lib/python3.8/site-packages/flask/app.py", line 1936, in dispatch_request
    return self.view_functions[rule.endpoint](**req.view_args)
  File "/Users/cham/Desktop/webproj2/faze/lib/python3.8/site-packages/flask_login/utils.py", line 272, in decorated_view
    return func(*args, **kwargs)
  File "/Users/cham/Desktop/webproj2/webproj2/app/routes.py", line 125, in view_answered
    return render_template('view_answered.html',answered=answered_questions)
  File "/Users/cham/Desktop/webproj2/faze/lib/python3.8/site-packages/flask/templating.py", line 138, in render_template
    ctx.app.jinja_env.get_or_select_template(template_name_or_list),
  File "/Users/cham/Desktop/webproj2/faze/lib/python3.8/site-packages/jinja2/environment.py", line 930, in get_or_select_template
    return self.get_template(template_name_or_list, parent, globals)
  File "/Users/cham/Desktop/webproj2/faze/lib/python3.8/site-packages/jinja2/environment.py", line 883, in get_template
    return self._load_template(name, self.make_globals(globals))
  File "/Users/cham/Desktop/webproj2/faze/lib/python3.8/site-packages/jinja2/environment.py", line 857, in _load_template
    template = self.loader.load(self, name, globals)
  File "/Users/cham/Desktop/webproj2/faze/lib/python3.8/site-packages/jinja2/loaders.py", line 127, in load
    code = environment.compile(source, name, filename)
  File "/Users/cham/Desktop/webproj2/faze/lib/python3.8/site-packages/jinja2/environment.py", line 638, in compile
    self.handle_exception(source=source_hint)
  File "/Users/cham/Desktop/webproj2/faze/lib/python3.8/site-packages/jinja2/environment.py", line 832, in handle_exception
    reraise(*rewrite_traceback_stack(source=source))
  File "/Users/cham/Desktop/webproj2/faze/lib/python3.8/site-packages/jinja2/_compat.py", line 28, in reraise
    raise value.with_traceback(tb)
  File "/Users/cham/Desktop/webproj2/webproj2/app/templates/view_answered.html", line 8, in template
    <hr> {% endblock %}
jinja2.exceptions.TemplateSyntaxError: Encountered unknown tag 'endblock'. You probably made a nesting mistake. Jinja is expecting this tag, but currently looking for 'endfor' or 'else'. The innermost block that needs to be closed is 'for'.
2020-05-15 15:26:21,786 INFO: quiz startup [in /Users/cham/Desktop/webproj2/webproj2/app/__init__.py:43]
2020-05-15 18:00:57,421 INFO: quiz startup [in /Users/cham/Desktop/webproj2/webproj2/app/__init__.py:43]
2020-05-15 18:01:31,055 INFO: quiz startup [in /Users/cham/Desktop/webproj2/webproj2/app/__init__.py:43]
2020-05-15 18:01:49,133 INFO: quiz startup [in /Users/cham/Desktop/webproj2/webproj2/app/__init__.py:43]
2020-05-15 18:02:35,055 INFO: quiz startup [in /Users/cham/Desktop/webproj2/webproj2/app/__init__.py:43]
2020-05-15 18:19:55,519 INFO: quiz startup [in /Users/cham/Desktop/webproj2/webproj2/app/__init__.py:43]
2020-05-15 18:20:00,691 ERROR: Exception on /view_answered [GET] [in /Users/cham/Desktop/webproj2/faze/lib/python3.8/site-packages/flask/app.py:1891]
Traceback (most recent call last):
  File "/Users/cham/Desktop/webproj2/faze/lib/python3.8/site-packages/flask/app.py", line 2447, in wsgi_app
    response = self.full_dispatch_request()
  File "/Users/cham/Desktop/webproj2/faze/lib/python3.8/site-packages/flask/app.py", line 1952, in full_dispatch_request
    rv = self.handle_user_exception(e)
  File "/Users/cham/Desktop/webproj2/faze/lib/python3.8/site-packages/flask/app.py", line 1821, in handle_user_exception
    reraise(exc_type, exc_value, tb)
  File "/Users/cham/Desktop/webproj2/faze/lib/python3.8/site-packages/flask/_compat.py", line 39, in reraise
    raise value
  File "/Users/cham/Desktop/webproj2/faze/lib/python3.8/site-packages/flask/app.py", line 1950, in full_dispatch_request
    rv = self.dispatch_request()
  File "/Users/cham/Desktop/webproj2/faze/lib/python3.8/site-packages/flask/app.py", line 1936, in dispatch_request
    return self.view_functions[rule.endpoint](**req.view_args)
  File "/Users/cham/Desktop/webproj2/faze/lib/python3.8/site-packages/flask_login/utils.py", line 272, in decorated_view
    return func(*args, **kwargs)
  File "/Users/cham/Desktop/webproj2/webproj2/app/routes.py", line 124, in view_answered
    answered_questions=Answer.query.all(answered_by=current_user.username)
TypeError: all() got an unexpected keyword argument 'answered_by'
2020-05-15 18:20:40,450 INFO: quiz startup [in /Users/cham/Desktop/webproj2/webproj2/app/__init__.py:43]
